<?xml version="1.0" ?>
<robot name="my_bot" xmlns:xacro="http://www.ros.org/wiki/xacro">

<xacro:include filename="$(find my_bot_description)/urdf/materials.xacro" />
<xacro:include filename="$(find my_bot_description)/urdf/my_bot.ros2control" />
<xacro:include filename="$(find my_bot_description)/urdf/my_bot.gazebo" />
<xacro:include filename="$(find my_bot_description)/urdf/my_bot.gazebo.xacro"/>

<link name="base_link">
  <inertial>
    <origin xyz="1.256274819339614e-10 -0.008310611955470804 0.041656746523611426" rpy="0 0 0"/>
    <mass value="7.779652496539071"/>
    <inertia ixx="0.025645" iyy="0.00826" izz="0.029489" ixy="-0.0" iyz="0.001457" ixz="0.0"/>
  </inertial>
  <visual>
    <origin xyz="0 0 0" rpy="0 0 0"/>
    <geometry>
      <mesh filename="file://$(find my_bot_description)/meshes/base_link.stl" scale="0.001 0.001 0.001"/>
    </geometry>
    <material name="silver"/>
  </visual>
  <collision>
    <origin xyz="0 0 0" rpy="0 0 0"/>
    <geometry>
      <mesh filename="file://$(find my_bot_description)/meshes/base_link.stl" scale="0.001 0.001 0.001"/>
    </geometry>
  </collision>
</link>

<link name="right_wheel_1">
  <inertial>
    <origin xyz="0.0075000000000000275 -1.0685896612017132e-15 -6.938893903907228e-18" rpy="0 0 0"/>
    <mass value="0.5895640400928156"/>
    <inertia ixx="0.000473" iyy="0.000248" izz="0.000248" ixy="-0.0" iyz="-0.0" ixz="0.0"/>
  </inertial>
  <visual>
    <origin xyz="-0.055 0.07 -0.04" rpy="0 0 0"/>
    <geometry>
      <mesh filename="file://$(find my_bot_description)/meshes/right_wheel_1.stl" scale="0.001 0.001 0.001"/>
    </geometry>
    <material name="silver"/>
  </visual>
  <collision>
    <origin xyz="-0.055 0.07 -0.04" rpy="0 0 0"/>
    <geometry>
      <mesh filename="file://$(find my_bot_description)/meshes/right_wheel_1.stl" scale="0.001 0.001 0.001"/>
    </geometry>
  </collision>
</link>

<link name="left_wheel_1">
  <inertial>
    <origin xyz="-0.0075000000000000275 -1.0685896612017132e-15 -6.938893903907228e-18" rpy="0 0 0"/>
    <mass value="0.5895640400928156"/>
    <inertia ixx="0.000473" iyy="0.000248" izz="0.000248" ixy="0.0" iyz="0.0" ixz="0.0"/>
  </inertial>
  <visual>
    <origin xyz="0.055 0.07 -0.04" rpy="0 0 0"/>
    <geometry>
      <mesh filename="file://$(find my_bot_description)/meshes/left_wheel_1.stl" scale="0.001 0.001 0.001"/>
    </geometry>
    <material name="silver"/>
  </visual>
  <collision>
    <origin xyz="0.055 0.07 -0.04" rpy="0 0 0"/>
    <geometry>
      <mesh filename="file://$(find my_bot_description)/meshes/left_wheel_1.stl" scale="0.001 0.001 0.001"/>
    </geometry>
  </collision>
</link>

<link name="lidar_1">
  <inertial>
    <origin xyz="4.825019250101691e-18 6.938893903907228e-18 0.007499999999999979" rpy="0 0 0"/>
    <mass value="0.23120158435012378"/>
    <inertia ixx="4e-05" iyy="4e-05" izz="7.2e-05" ixy="-0.0" iyz="0.0" ixz="0.0"/>
  </inertial>
  <visual>
    <origin xyz="-0.0 0.06 -0.095" rpy="0 0 0"/>
    <geometry>
      <mesh filename="file://$(find my_bot_description)/meshes/lidar_1.stl" scale="0.001 0.001 0.001"/>
    </geometry>
    <material name="silver"/>
  </visual>
  <collision>
    <origin xyz="-0.0 0.06 -0.095" rpy="0 0 0"/>
    <geometry>
      <mesh filename="file://$(find my_bot_description)/meshes/lidar_1.stl" scale="0.001 0.001 0.001"/>
    </geometry>
  </collision>
</link>

<link name="caster_wheel_1">
  <inertial>
    <origin xyz="-4.24073957528469e-18 -0.04 -0.007499999999999997" rpy="0 0 0"/>
    <mass value="0.1315280124302926"/>
    <inertia ixx="1.4e-05" iyy="1.4e-05" izz="2.1e-05" ixy="-0.0" iyz="0.0" ixz="-0.0"/>
  </inertial>
  <visual>
    <origin xyz="-0.0 -0.095 -0.015" rpy="0 0 0"/>
    <geometry>
      <mesh filename="file://$(find my_bot_description)/meshes/caster_wheel_1.stl" scale="0.001 0.001 0.001"/>
    </geometry>
    <material name="silver"/>
  </visual>
  <collision>
    <origin xyz="-0.0 -0.095 -0.015" rpy="0 0 0"/>
    <geometry>
      <mesh filename="file://$(find my_bot_description)/meshes/caster_wheel_1.stl" scale="0.001 0.001 0.001"/>
    </geometry>
  </collision>
</link>

<joint name="Revolute 1" type="continuous">
  <origin xyz="0.055 -0.07 0.04" rpy="0 0 0"/>
  <parent link="base_link"/>
  <child link="right_wheel_1"/>
  <axis xyz="1.0 0.0 0.0"/>
</joint>

<joint name="Revolute 2" type="continuous">
  <origin xyz="-0.055 -0.07 0.04" rpy="0 0 0"/>
  <parent link="base_link"/>
  <child link="left_wheel_1"/>
  <axis xyz="-1.0 0.0 0.0"/>
</joint>

<joint name="Rigid 3" type="fixed">
  <origin xyz="0.0 -0.06 0.095" rpy="0 0 0"/>
  <parent link="base_link"/>
  <child link="lidar_1"/>
</joint>

<joint name="Rigid 4" type="fixed">
  <origin xyz="0.0 0.095 0.015" rpy="0 0 0"/>
  <parent link="base_link"/>
  <child link="caster_wheel_1"/>
</joint>

</robot>
